<?xml version="1.0"?>
<robot name="IGRIS_C">
  <!-- ### LINK ### -->
  <link name="base_link">
    <inertial>
      <mass value="12.974" />
      <origin xyz="0.00175 0.00112 0.15154" />
      <inertia ixx="0.15110" ixy="-0.00136" ixz="0.00843" iyy="0.12880" iyz="-0.00089" izz="0.08070" />
    </inertial>
    <visual>
      <geometry>
        <mesh filename="/home/robros/isaac_ws/IGRIS_GYM/resources/robots/igris/meshes/igris_c_v2/Waist_Yaw.stl" scale="0.01 0.01 0.01"/>
      </geometry>
      <material name="random">
        <color rgba="0.0706 0.0706 0.0706 0.7" />
      </material>
    </visual>
    <collision>
      <origin xyz="0.0 0.0 0.17" />
      <geometry>
        <box size="0.22 0.23 0.33"/>
      </geometry>
    </collision>
  </link>

  <!-- WAIST -->
  <link name="Link_Waist_Yaw">
    <inertial>
      <mass value="0.208" />
      <origin xyz="0.02597 0.00000 -0.00927" />
      <inertia ixx="0.00031" ixy="0.00000" ixz="0.00003" iyy="0.00031" iyz="0.00000" izz="0.00058" />
    </inertial>
    <visual>
      <geometry>
        <mesh filename="/home/robros/isaac_ws/IGRIS_GYM/resources/robots/igris/meshes/igris_c_v2/Waist_Yaw_B.stl" scale="0.01 0.01 0.01"/>
      </geometry>
      <material name="random">
        <color rgba="0.0706 0.0706 0.0706 0.7" />
      </material>
    </visual>
  </link>

  <link name="Link_Waist_Roll">
    <inertial>
      <mass value="0.136" />
      <origin xyz="0.00000 0.00000 -0.00829" />
      <inertia ixx="0.00005" ixy="0.00000" ixz="0.00000" iyy="0.00011" iyz="0.00000" izz="0.00007" />
    </inertial>
    <visual>
      <geometry>
        <mesh filename="/home/robros/isaac_ws/IGRIS_GYM/resources/robots/igris/meshes/igris_c_v2/Waist_Roll_B.stl" scale="0.01 0.01 0.01"/>
      </geometry>
      <material name="random">
        <color rgba="0.0706 0.0706 0.0706 0.7" />
      </material>
    </visual>
  </link>


  <link name="Link_Waist_Pitch">
    <inertial>
      <mass value="8.124" />
      <origin xyz="-0.03810 -0.00001 0.08837" />
      <inertia ixx="0.04342" ixy="0.00001" ixz="0.00325" iyy="0.05156" iyz="0.00000" izz="0.04212" />
    </inertial>
    <visual>
      <geometry>
        <mesh filename="/home/robros/isaac_ws/IGRIS_GYM/resources/robots/igris/meshes/igris_c_v2/Waist_Pitch_B.stl" scale="0.01 0.01 0.01"/>
      </geometry>
      <material name="random">
        <color rgba="0.0706 0.0706 0.0706 0.7" />
      </material>
    </visual>
  </link>


  <!-- LEFT LEG -->
  <link name="Link_Hip_Pitch_Left">
    <inertial>
      <mass value="1.894" />
      <origin xyz="0.00973 -0.00102 0.00002" />
      <inertia ixx="0.00261" ixy="-0.00001" ixz="0.00000" iyy="0.00267" iyz="0.00000" izz="0.00258" />
    </inertial>
    <visual>
      <geometry>
        <mesh filename="/home/robros/isaac_ws/IGRIS_GYM/resources/robots/igris/meshes/igris_c_v2/Hip_Pitch_Left.stl" scale="0.01 0.01 0.01"/>
      </geometry>
      <material name="random">
        <color rgba="0.0706 0.0706 0.0706 0.7" />
      </material>
    </visual>
  </link>

  <link name="Link_Hip_Roll_Left">
    <inertial>
      <mass value="0.573" />
      <origin xyz="-0.01497 0.00570 -0.03564" />
      <inertia ixx="0.00103" ixy="-0.00006" ixz="0.00012" iyy="0.00226" iyz="0.00006" izz="0.00206" />
    </inertial>
    <visual>
      <geometry>
        <mesh filename="/home/robros/isaac_ws/IGRIS_GYM/resources/robots/igris/meshes/igris_c_v2/Hip_Roll_Left.stl" scale="0.01 0.01 0.01"/>
      </geometry>
      <material name="random">
        <color rgba="0.0706 0.0706 0.0706 0.7" />
      </material>
    </visual>
    <!-- <collision>
      <origin xyz="-0.015 0.0 -0.005" rpy="0 0 0"/>
      <geometry>
        <box size="0.16 0.12 0.12"/>
      </geometry>
    </collision> -->
  </link>

    <link name="Link_Hip_Yaw_Left">
    <inertial>
      <mass value="4.813" />
      <origin xyz="-0.01286 -0.00388 -0.10563" />
      <inertia ixx="0.03161" ixy="-0.00007" ixz="-0.00101" iyy="0.03396" iyz="-0.00084" izz="0.01135" />
    </inertial>
    <visual>
      <geometry>
        <mesh filename="/home/robros/isaac_ws/IGRIS_GYM/resources/robots/igris/meshes/igris_c_v2/Hip_Yaw_Left.stl" scale="0.01 0.01 0.01"/>
      </geometry>
      <material name="random">
        <color rgba="0.0706 0.0706 0.0706 0.7" />
      </material>
    </visual>
  </link>

  <link name="Link_Knee_Pitch_Left">
    <inertial>
      <mass value="3.212" />
      <origin xyz="0.01044 0.00096 -0.12320" />
      <inertia ixx="0.02686" ixy="0.00000" ixz="-0.00201" iyy="0.02845" iyz="-0.00048" izz="0.00520" />
    </inertial>
    <visual>
      <geometry>
        <mesh filename="/home/robros/isaac_ws/IGRIS_GYM/resources/robots/igris/meshes/igris_c_v2/Knee_Pitch_Left.stl" scale="0.01 0.01 0.01"/>
      </geometry>
      <material name="random">
        <color rgba="0.0706 0.0706 0.0706 0.7" />
      </material>
    </visual>
    <collision>
      <origin xyz="0.02 0.0 -0.10" />
      <geometry>
        <box size="0.15 0.1 0.25"/>
      </geometry>
    </collision>
  </link>

    <link name="Link_Ankle_Pitch_Left">
    <inertial>
      <mass value="0.084" />
      <origin xyz="0.00000 0.00000 0.00000" />
      <inertia ixx="0.00003" ixy="0.00000" ixz="0.00000" iyy="0.00002" iyz="0.00000" izz="0.00003" />
    </inertial>
    <visual>
      <geometry>
        <mesh filename="/home/robros/isaac_ws/IGRIS_GYM/resources/robots/igris/meshes/igris_c_v2/Ankle_Pitch_Left.stl" scale="0.01 0.01 0.01"/>
      </geometry>
      <material name="random">
        <color rgba="0.0706 0.0706 0.0706 0.7" />
      </material>
    </visual>
  </link>

  <link name="Link_Ankle_Roll_Left">
    <inertial>
      <mass value="0.459" />
      <origin xyz="0.02167 0.00000 -0.05193" />
      <inertia ixx="0.00045" ixy="0.00000" ixz="0.00024" iyy="0.00166" iyz="0.00000" izz="0.00158" />
    </inertial>
    <visual>
      <geometry>
        <mesh filename="/home/robros/isaac_ws/IGRIS_GYM/resources/robots/igris/meshes/igris_c_v2/Ankle_Roll_Left.stl" scale="0.01 0.01 0.01"/>
      </geometry>
      <material name="random">
        <color rgba="0.0706 0.0706 0.0706 0.7" />
      </material>
    </visual>
    <collision>
      <origin xyz="0.048 0.0 -0.073" />
      <geometry>
        <box size="0.2 0.07 0.014"/>
      </geometry>
    </collision>
  </link>

  <!-- RIGHT LEG -->
  <link name="Link_Hip_Pitch_Right">
    <inertial>
      <mass value="1.894" />
      <origin xyz="0.00973 0.00102 -0.00002" />
      <inertia ixx="0.00261" ixy="0.00001" ixz="0.00000" iyy="0.00267" iyz="0.00000" izz="0.00258" />
    </inertial>
    <visual>
      <geometry>
        <mesh filename="/home/robros/isaac_ws/IGRIS_GYM/resources/robots/igris/meshes/igris_c_v2/Hip_Pitch_Right.stl" scale="0.01 0.01 0.01"/>
      </geometry>
      <material name="random">
        <color rgba="0.0706 0.0706 0.0706 0.7" />
      </material>
    </visual>
  </link>

  <link name="Link_Hip_Roll_Right">
    <inertial>
      <mass value="0.573" />
      <origin xyz="-0.01497 -0.00570 -0.03564" />
      <inertia ixx="0.00103" ixy="0.00006" ixz="0.00012" iyy="0.00226" iyz="-0.00006" izz="0.00206" />
    </inertial>
    <visual>
      <geometry>
        <mesh filename="/home/robros/isaac_ws/IGRIS_GYM/resources/robots/igris/meshes/igris_c_v2/Hip_Roll_Right.stl" scale="0.01 0.01 0.01"/>
      </geometry>
      <material name="random">
        <color rgba="0.0706 0.0706 0.0706 0.7" />
      </material>
    </visual>
    <!-- <collision>
      <origin xyz="-0.015 0.0 -0.005" rpy="0 0 0"/>
      <geometry>
        <box size="0.16 0.12 0.12"/>
      </geometry>
    </collision> -->
  </link>

  <link name="Link_Hip_Yaw_Right">
    <inertial>
      <mass value="4.813" />
      <origin xyz="-0.01286 0.00388 -0.10564" />
      <inertia ixx="0.03161" ixy="0.00007" ixz="-0.00101" iyy="0.03398" iyz="0.00084" izz="0.01137" />
    </inertial>
    <visual>
      <geometry>
        <mesh filename="/home/robros/isaac_ws/IGRIS_GYM/resources/robots/igris/meshes/igris_c_v2/Hip_Yaw_Right.stl" scale="0.01 0.01 0.01"/>
      </geometry>
      <material name="random">
        <color rgba="0.0706 0.0706 0.0706 0.7" />
      </material>
    </visual>
  </link>

  <link name="Link_Knee_Pitch_Right">
    <inertial>
      <mass value="3.212" />
      <origin xyz="0.01044 -0.00096 -0.12320" />
      <inertia ixx="0.02686" ixy="0.00000" ixz="-0.00201" iyy="0.02845" iyz="0.00048" izz="0.00520" />
    </inertial>
    <visual>
      <geometry>
        <mesh filename="/home/robros/isaac_ws/IGRIS_GYM/resources/robots/igris/meshes/igris_c_v2/Knee_Pitch_Right.stl" scale="0.01 0.01 0.01"/>
      </geometry>
      <material name="random">
        <color rgba="0.0706 0.0706 0.0706 0.7" />
      </material>
    </visual>
    <collision>
      <origin xyz="0.02 0.0 -0.10" />
      <geometry>
        <box size="0.15 0.1 0.25"/>
      </geometry>
    </collision>
  </link>

  <link name="Link_Ankle_Pitch_Right">
    <inertial>
      <mass value="0.084" />
      <origin xyz="0 0 0" />
      <inertia ixx="0.00003" ixy="0.00000" ixz="0.00000" iyy="0.00002" iyz="0.00000" izz="0.00003" />
    </inertial>
    <visual>
      <geometry>
        <mesh filename="/home/robros/isaac_ws/IGRIS_GYM/resources/robots/igris/meshes/igris_c_v2/Ankle_Pitch_Right.stl" scale="0.01 0.01 0.01"/>
      </geometry>
      <material name="random">
        <color rgba="0.0706 0.0706 0.0706 0.7" />
      </material>
    </visual>
  </link>

  <link name="Link_Ankle_Roll_Right">
    <inertial>
      <mass value="0.459" />
      <origin xyz="0.02167 0.00000 -0.05193" />
      <inertia ixx="0.00045" ixy="0.00000" ixz="0.00024" iyy="0.00166" iyz="0.00000" izz="0.00158" />
    </inertial>
    <visual>
      <geometry>
        <mesh filename="/home/robros/isaac_ws/IGRIS_GYM/resources/robots/igris/meshes/igris_c_v2/Ankle_Roll_Right.stl" scale="0.01 0.01 0.01"/>
      </geometry>
      <material name="random">
        <color rgba="0.0706 0.0706 0.0706 0.7" />
      </material>
    </visual>
    <collision>
      <origin xyz="0.048 0.0 -0.073" />
      <geometry>
        <box size="0.2 0.07 0.014"/>
      </geometry>
    </collision>
  </link>

  <!-- LEFT ARM -->
  <link name="Link_Shoulder_Pitch_Left">
    <inertial>
      <mass value="1.105" />
      <origin xyz="0.00039 -0.00330 0.00004" />
      <inertia ixx="0.00118" ixy="0.00001" ixz="0.00000" iyy="0.00097" iyz="0.00000" izz="0.00107" />
    </inertial>
    <visual>
      <geometry>
        <mesh filename="/home/robros/isaac_ws/IGRIS_GYM/resources/robots/igris/meshes/igris_c_v2/Shoulder_Pitch_Left.stl" scale="0.01 0.01 0.01"/>
      </geometry>
      <material name="random">
        <color rgba="0.0706 0.0706 0.0706 0.7" />
      </material>
    </visual>
  </link>

  <link name="Link_Shoulder_Roll_Left">
    <inertial>
      <mass value="0.253" />
      <origin xyz="0.02322 0.00000 -0.03100" />
      <inertia ixx="0.00046" ixy="0.00000" ixz="-0.00013" iyy="0.00046" iyz="0.00000" izz="0.00034" />
    </inertial>
    <visual>
      <geometry>
        <mesh filename="/home/robros/isaac_ws/IGRIS_GYM/resources/robots/igris/meshes/igris_c_v2/Shoulder_Roll_Left.stl" scale="0.01 0.01 0.01"/>
      </geometry>
      <material name="random">
        <color rgba="0.0706 0.0706 0.0706 0.7" />
      </material>
    </visual>
  </link>

  <link name="Link_Shoulder_Yaw_Left">
    <inertial>
      <mass value="2.144" />
      <origin xyz="0.00289 0.00039 -0.14632" />
      <inertia ixx="0.00708" ixy="0.00000" ixz="0.00045" iyy="0.00723" iyz="0.00002" izz="0.00213" />
    </inertial>
    <visual>
      <geometry>
        <mesh filename="/home/robros/isaac_ws/IGRIS_GYM/resources/robots/igris/meshes/igris_c_v2/Shoulder_Yaw_Left.stl" scale="0.01 0.01 0.01"/>
      </geometry>
      <material name="random">
        <color rgba="0.0706 0.0706 0.0706 0.7" />
      </material>
    </visual>
  </link>

  <link name="Link_Elbow_Pitch_Left">
    <inertial>
      <mass value="0.137" />
      <origin xyz="-0.00506 0.02516 -0.02257" />
      <inertia ixx="0.00017" ixy="-0.00001" ixz="-0.00002" iyy="0.00017" iyz="-0.00005" izz="0.00013" />
    </inertial>
    <visual>
      <geometry>
        <mesh filename="/home/robros/isaac_ws/IGRIS_GYM/resources/robots/igris/meshes/igris_c_v2/Elbow_Pitch_Left.stl" scale="0.01 0.01 0.01"/>
      </geometry>
      <material name="random">
        <color rgba="0.0706 0.0706 0.0706 0.7" />
      </material>
    </visual>
  </link>

  <link name="Link_Wrist_Yaw_Left">
    <inertial>
      <mass value="2.428" />
      <origin xyz="-0.00010 -0.00047 -0.08726" />
      <inertia ixx="0.00890" ixy="0.00000" ixz="-0.00003" iyy="0.00984" iyz="-0.00002" izz="0.00313" />
    </inertial>
    <visual>
      <geometry>
        <mesh filename="/home/robros/isaac_ws/IGRIS_GYM/resources/robots/igris/meshes/igris_c_v2/Wrist_Yaw_Left.stl" scale="0.01 0.01 0.01"/>
      </geometry>
      <material name="random">
        <color rgba="0.0706 0.0706 0.0706 0.7" />
      </material>
    </visual>
    <collision>
      <origin xyz="0.0 0.0 -0.12" rpy="0 0 0"/>
      <geometry>
         <cylinder radius="0.05" length="0.24"/>
      </geometry>
    </collision>
  </link>

  <link name="Link_Wrist_Roll_Left">
    <inertial>
      <mass value="0.012" />
      <origin xyz="0.00000 0.00604 0.00031" />
      <inertia ixx="0.00001" ixy="0.00000" ixz="0.00000" iyy="0.00001" iyz="0.00000" izz="0.00001" />
    </inertial>
    <visual>
      <geometry>
        <mesh filename="/home/robros/isaac_ws/IGRIS_GYM/resources/robots/igris/meshes/igris_c_v2/Wrist_Roll_Left.stl" scale="0.01 0.01 0.01"/>
      </geometry>
      <material name="random">
        <color rgba="0.0706 0.0706 0.0706 0.7" />
      </material>
    </visual>
  </link>

  <link name="Link_Wrist_Pitch_Left">
    <inertial>
      <mass value="0.020" />
      <origin xyz="0 0.01019 -0.01687" />
      <inertia ixx="0.00001" ixy="0.00000" ixz="0.00000" iyy="0.00001" iyz="0.00000" izz="0.00001" />
    </inertial>
    <visual>
      <geometry>
        <mesh filename="/home/robros/isaac_ws/IGRIS_GYM/resources/robots/igris/meshes/igris_c_v2/Wrist_Pitch_Left.stl" scale="0.01 0.01 0.01"/>
      </geometry>
      <material name="random">
        <color rgba="0.0706 0.0706 0.0706 0.7" />
      </material>
    </visual>
  </link>
  
  <link name="Left_Hand">
    <inertial>
      <mass value="0.333" />
      <origin xyz="0.00910 0.00371 0.07839" />
      <inertia ixx="0.00081" ixy="-0.00004" ixz="0.00012" iyy="0.00117" iyz="0.00005" izz="0.00042" />
    </inertial>
    <visual>
      <geometry>
        <mesh filename="/home/robros/isaac_ws/IGRIS_GYM/resources/robots/igris/meshes/igris_c_v2/Hand_Left.stl" scale="0.01 0.01 0.01"/>
      </geometry>
      <material name="random">
        <color rgba="0.0706 0.0706 0.0706 0.7" />
      </material>
    </visual>
    <collision>
      <origin xyz="0.02 0.0 0.1" rpy="0 0 0"/>
      <geometry>
        <box size="0.15 0.05 0.2"/>
      </geometry>
    </collision>
  </link>

  <!-- RIGHT ARM -->
  <link name="Link_Shoulder_Pitch_Right">
    <inertial>
      <mass value="1.105" />
      <origin xyz="0.00039 0.00330 -0.00004" />
      <inertia ixx="0.00118" ixy="-0.00001" ixz="0.00000" iyy="0.00097" iyz="0.00000" izz="0.00107" />
    </inertial>
    <visual>
      <geometry>
        <mesh filename="/home/robros/isaac_ws/IGRIS_GYM/resources/robots/igris/meshes/igris_c_v2/Shoulder_Pitch_Right.stl" scale="0.01 0.01 0.01"/>
      </geometry>
      <material name="random">
        <color rgba="0.0706 0.0706 0.0706 0.7" />
      </material>
    </visual>
  </link>

  <link name="Link_Shoulder_Roll_Right">
    <inertial>
      <mass value="0.253" />
      <origin xyz="0.02322 0.00000 -0.03100" />
      <inertia ixx="0.00046" ixy="0.00000" ixz="-0.00013" iyy="0.00046" iyz="0.00000" izz="0.00034" />
    </inertial>
    <visual>
      <geometry>
        <mesh filename="/home/robros/isaac_ws/IGRIS_GYM/resources/robots/igris/meshes/igris_c_v2/Shoulder_Roll_Right.stl" scale="0.01 0.01 0.01"/>
      </geometry>
      <material name="random">
        <color rgba="0.0706 0.0706 0.0706 0.7" />
      </material>
    </visual>
  </link>

  <link name="Link_Shoulder_Yaw_Right">
    <inertial>
      <mass value="2.144" />
      <origin xyz="0.00289 -0.00018 -0.14632" />
      <inertia ixx="0.00708" ixy="0.00001" ixz="0.00045" iyy="0.00723" iyz="-0.00002" izz="0.00213" />
    </inertial>
    <visual>
      <geometry>
        <mesh filename="/home/robros/isaac_ws/IGRIS_GYM/resources/robots/igris/meshes/igris_c_v2/Shoulder_Yaw_Right.stl" scale="0.01 0.01 0.01"/>
      </geometry>
      <material name="random">
        <color rgba="0.0706 0.0706 0.0706 0.7" />
      </material>
    </visual>
  </link>

  <link name="Link_Elbow_Pitch_Right">
    <inertial>
      <mass value="0.137" />
      <origin xyz="-0.00506 -0.02516 -0.02257" />
      <inertia ixx="0.00017" ixy="0.00001" ixz="-0.00002" iyy="0.00017" iyz="0.00005" izz="0.00013" />
    </inertial>
    <visual>
      <geometry>
        <mesh filename="/home/robros/isaac_ws/IGRIS_GYM/resources/robots/igris/meshes/igris_c_v2/Elbow_Pitch_Right.stl" scale="0.01 0.01 0.01"/>
      </geometry>
      <material name="random">
        <color rgba="0.0706 0.0706 0.0706 0.7" />
      </material>
    </visual>
  </link>

  <link name="Link_Wrist_Yaw_Right">
    <inertial>
      <mass value="2.428" />
      <origin xyz="0.00011 0.00044 -0.08726" />
      <inertia ixx="0.00890" ixy="0.00000" ixz="0.00003" iyy="0.00984" iyz="0.00001" izz="0.00313" />
    </inertial>
    <visual>
      <geometry>
        <mesh filename="/home/robros/isaac_ws/IGRIS_GYM/resources/robots/igris/meshes/igris_c_v2/Wrist_Yaw_Right.stl" scale="0.01 0.01 0.01"/>
      </geometry>
      <material name="random">
        <color rgba="0.0706 0.0706 0.0706 0.7" />
      </material>
    </visual>
    <collision>
      <origin xyz="0.0 0.0 -0.12" rpy="0 0 0"/>
      <geometry>
         <cylinder radius="0.05" length="0.24"/>
      </geometry>
    </collision>
  </link>

  <link name="Link_Wrist_Roll_Right">
    <inertial>
      <mass value="0.012" />
      <origin xyz="0.00000 -0.00604 0.00031" />
      <inertia ixx="0.00001" ixy="0.00000" ixz="0.00000" iyy="0.00001" iyz="0.00000" izz="0.00001" />
    </inertial>
    <visual>
      <geometry>
        <mesh filename="/home/robros/isaac_ws/IGRIS_GYM/resources/robots/igris/meshes/igris_c_v2/Wrist_Roll_Right.stl" scale="0.01 0.01 0.01"/>
      </geometry>
      <material name="random">
        <color rgba="0.0706 0.0706 0.0706 0.7" />
      </material>
    </visual>
  </link>

  <link name="Link_Wrist_Pitch_Right">
    <inertial>
      <mass value="0.020" />
      <origin xyz="0.00000 -0.01019 -0.01687" />
      <inertia ixx="0.00001" ixy="0.00000" ixz="0.00000" iyy="0.00001" iyz="0.00000" izz="0.00001" />
    </inertial>
    <visual>
      <geometry>
        <mesh filename="/home/robros/isaac_ws/IGRIS_GYM/resources/robots/igris/meshes/igris_c_v2/Wrist_Pitch_Right.stl" scale="0.01 0.01 0.01"/>
      </geometry>
      <material name="random">
        <color rgba="0.0706 0.0706 0.0706 0.7" />
      </material>
    </visual>
  </link>

  <link name="Right_Hand">
      <inertial>
        <mass value="0.333" />
        <origin xyz="0.00910 -0.00371 0.07839" />
        <inertia ixx="0.00081" ixy="0.00004" ixz="0.00012" iyy="0.00117" iyz="-0.00005" izz="0.00042" />
      </inertial>
      <visual>
        <geometry>
          <mesh filename="/home/robros/isaac_ws/IGRIS_GYM/resources/robots/igris/meshes/igris_c_v2/Hand_Right.stl" scale="0.01 0.01 0.01"/>
        </geometry>
        <material name="random">
          <color rgba="0.0706 0.0706 0.0706 0.7" />
        </material>
      </visual>
      <collision>
        <origin xyz="0.02 0.0 0.1" rpy="0 0 0"/>
        <geometry>
          <box size="0.15 0.05 0.2"/>
        </geometry>
      </collision>
  </link>

  <!-- HEAD -->
  <link name="Link_Neck_Yaw">
    <inertial>
      <mass value="0.310" />
      <origin xyz="-0.00005 -0.00130 -0.00264" />
      <inertia ixx="0.00017" ixy="0.00000" ixz="0.00000" iyy="0.00010" iyz="0.00001" izz="0.00016" />
    </inertial>
    <visual>
      <geometry>
        <mesh filename="/home/robros/isaac_ws/IGRIS_GYM/resources/robots/igris/meshes/igris_c_v2/Neck_Yaw.stl" scale="0.01 0.01 0.01"/>
      </geometry>
      <material name="random">
        <color rgba="0.0706 0.0706 0.0706 0.7" />
      </material>
    </visual>
  </link>

  <link name="Link_Neck_Pitch">
    <inertial>
      <mass value="1.468" />
      <origin xyz="0.02850 0.00290 0.12862" />
      <inertia ixx="0.00574" ixy="-0.00008" ixz="0.00025" iyy="0.00727" iyz="0.00013" izz="0.00503" />
    </inertial>
    <visual>
      <geometry>
        <mesh filename="/home/robros/isaac_ws/IGRIS_GYM/resources/robots/igris/meshes/igris_c_v2/Neck_Pitch.stl" scale="0.01 0.01 0.01"/>
      </geometry>
      <material name="random">
        <color rgba="0.0706 0.0706 0.0706 0.7" />
      </material>
    </visual>
    <collision>
      <origin xyz="0.025 0.0 0.12" />
      <geometry>
        <box size="0.2 0.15 0.18"/>
      </geometry>
    </collision>
  </link>

  <!-- ### JOINT ### -->

  <!-- WAIST -->
  <joint name="Joint_Waist_Yaw" type="fixed">
    <parent link="base_link" />
    <child link="Link_Waist_Yaw" />
    <origin xyz="0 0 0" rpy="0 0 0" />
  </joint>
 
  <joint name="Joint_Waist_Roll" type="fixed">
    <parent link="Link_Waist_Yaw" />
    <child link="Link_Waist_Roll" />
    <origin xyz="0.05 0 -0.026" rpy="0 0 0" />
  </joint>
  
  <joint name="Joint_Waist_Pitch" type="fixed">
    <parent link="Link_Waist_Roll" />
    <child link="Link_Waist_Pitch" />
    <origin xyz="0 0 -0.04" rpy="0 0 0" />
  </joint>


  <!-- LEFT LEG -->
  <joint name="Joint_Hip_Pitch_Left" type="revolute">
    <parent link="Link_Waist_Pitch" />
    <child link="Link_Hip_Pitch_Left" />
    <origin xyz="-0.0115 0.0897 -0.14" rpy="0 0 0" />
    <axis xyz="0 1 0" />
    <limit lower="-3.14" upper="1.57" effort="1000" velocity="100.0" />
  </joint>

  <joint name="Joint_Hip_Roll_Left" type="revolute">
    <parent link="Link_Hip_Pitch_Left" />
    <child link="Link_Hip_Roll_Left" />
    <origin xyz="0 0 0" rpy="0 0 0" />
    <axis xyz="1 0 0" />
    <limit lower="-1.57" upper="3.14" effort="1000" velocity="100.0" />
  </joint>

  <joint name="Joint_Hip_Yaw_Left" type="revolute">
    <parent link="Link_Hip_Roll_Left" />
    <child link="Link_Hip_Yaw_Left" />
    <origin xyz="0.002 0 -0.076" rpy="0 0 0" />
    <axis xyz="0 0 1" />
    <limit lower="-1.570796327" upper="1.570796327" effort="1000" velocity="100.0" />
  </joint>

  <joint name="Joint_Knee_Pitch_Left" type="revolute">
    <parent link="Link_Hip_Yaw_Left" />
    <child link="Link_Knee_Pitch_Left" />
    <origin xyz="-0.055 0 -0.263" rpy="0 0 0" />
    <axis xyz="0 1 0" />
    <limit lower="0.5" upper="3.14" effort="1000" velocity="100.0" />
  </joint>

  <joint name="Joint_Ankle_Pitch_Left" type="revolute">
    <parent link="Link_Knee_Pitch_Left" />
    <child link="Link_Ankle_Pitch_Left" />
    <origin xyz="0.005 0 -0.34" rpy="0 0 0" />
    <axis xyz="0 1 0" />
    <limit lower="-1.57" upper="1.57" effort="1000" velocity="100.0" />
  </joint>

  <joint name="Joint_Ankle_Roll_Left" type="revolute">
    <parent link="Link_Ankle_Pitch_Left" />
    <child link="Link_Ankle_Roll_Left" />
    <origin xyz="0 0 0" rpy="0 0 0" />
    <axis xyz="1 0 0" />
    <limit lower="-1.57" upper="1.57" effort="1000" velocity="100.0" />
  </joint>

  <!-- RIGHT LEG -->
  <joint name="Joint_Hip_Pitch_Right" type="revolute">
    <parent link="Link_Waist_Pitch" />
    <child link="Link_Hip_Pitch_Right" />
    <origin xyz="-0.0155 -0.0897 -0.14" rpy="0 0 0" />
    <axis xyz="0 1 0" />
    <limit lower="-3.14" upper="1.57" effort="1000" velocity="100.0" />
  </joint>

  <joint name="Joint_Hip_Roll_Right" type="revolute">
    <parent link="Link_Hip_Pitch_Right" />
    <child link="Link_Hip_Roll_Right" />
    <origin xyz="0 0 0" rpy="0 0 0" />
    <axis xyz="1 0 0" />
    <limit lower="-3.14" upper="1.57" effort="1000" velocity="100.0" />
  </joint>

  <joint name="Joint_Hip_Yaw_Right" type="revolute">
    <parent link="Link_Hip_Roll_Right" />
    <child link="Link_Hip_Yaw_Right" />
    <origin xyz="0.002 0 -0.076" rpy="0 0 0" />
    <axis xyz="0 0 1" />
    <limit lower="-1.570796327" upper="1.570796327" effort="1000" velocity="100.0" />
  </joint>

  <joint name="Joint_Knee_Pitch_Right" type="revolute">
    <parent link="Link_Hip_Yaw_Right" />
    <child link="Link_Knee_Pitch_Right" />
    <origin xyz="-0.055 0 -0.263" rpy="0 0 0" />
    <axis xyz="0 1 0" />
    <limit lower="0.5" upper="3.14" effort="1000" velocity="100.0" />
  </joint>

  <joint name="Joint_Ankle_Pitch_Right" type="revolute">
    <parent link="Link_Knee_Pitch_Right" />
    <child link="Link_Ankle_Pitch_Right" />
    <origin xyz="0.005 0 -0.34" rpy="0 0 0" />
    <axis xyz="0 1 0" />
    <limit lower="-1.57" upper="1.57" effort="1000" velocity="100.0" />
  </joint>

  <joint name="Joint_Ankle_Roll_Right" type="revolute">
    <parent link="Link_Ankle_Pitch_Right" />
    <child link="Link_Ankle_Roll_Right" />
    <origin xyz="0 0 0" rpy="0 0 0" />
    <axis xyz="1 0 0" />
    <limit lower="-1.57" upper="1.57" effort="1000" velocity="100.0" />
  </joint>

  <!-- LEFT ARM -->
  <joint name="Joint_Shoulder_Pitch_Left" type="fixed">
    <parent link="base_link" />
    <child link="Link_Shoulder_Pitch_Left" />
    <origin xyz="0 0.171 0.266" rpy="0 0.4 0" />
  </joint>

  <joint name="Joint_Shoulder_Roll_Left" type="fixed">
    <parent link="Link_Shoulder_Pitch_Left" />
    <child link="Link_Shoulder_Roll_Left" />
    <origin xyz="0 0 0" rpy="0.13 0 0" />
  </joint>

  <joint name="Joint_Shoulder_Yaw_Left" type="fixed">
    <parent link="Link_Shoulder_Roll_Left" />
    <child link="Link_Shoulder_Yaw_Left" />
    <origin xyz="0 0 0" rpy="0 0 0" />
  </joint>

  <joint name="Joint_Elbow_Pitch_Left" type="fixed">
    <parent link="Link_Shoulder_Yaw_Left" />
    <child link="Link_Elbow_Pitch_Left" />
    <origin xyz="0.01 0 -0.197" rpy="0 -1.9 0" />
  </joint>

  <joint name="Joint_Wrist_Yaw_Left" type="fixed">
    <parent link="Link_Elbow_Pitch_Left" />
    <child link="Link_Wrist_Yaw_Left" />
    <origin xyz="-0.01 0 -0.05" rpy="0 0 0" />
  </joint>

  <joint name="Joint_Wrist_Roll_Left" type="fixed">
    <parent link="Link_Wrist_Yaw_Left" />
    <child link="Link_Wrist_Roll_Left" />
    <origin xyz="0 -0.005 -0.2395 " rpy="0 0 0" />
  </joint>

  <joint name="Joint_Wrist_Pitch_Left" type="fixed">
    <parent link="Link_Wrist_Roll_Left" />
    <child link="Link_Wrist_Pitch_Left" />
    <origin xyz="0 0 0" rpy="0 0 0" />
  </joint>

  <joint name="Left_Hand" type="fixed">
    <parent link="Link_Wrist_Pitch_Left" />
    <child link="Left_Hand" />
    <origin xyz="0 0.0109 -0.024" rpy="3.14 0 0" />
  </joint>

  <!-- RIGHT ARM -->
  <joint name="Joint_Shoulder_Pitch_Right" type="fixed">
    <parent link="base_link" />
    <child link="Link_Shoulder_Pitch_Right" />
    <origin xyz="0 -0.171 0.266" rpy="0 0.4 0" />
  </joint>

  <joint name="Joint_Shoulder_Roll_Right" type="fixed">
    <parent link="Link_Shoulder_Pitch_Right" />
    <child link="Link_Shoulder_Roll_Right" />
    <origin xyz="0 0 0" rpy="-0.13 0 0" />
  </joint>

  <joint name="Joint_Shoulder_Yaw_Right" type="fixed">
    <parent link="Link_Shoulder_Roll_Right" />
    <child link="Link_Shoulder_Yaw_Right" />
    <origin xyz="0 0 0" rpy="0 0 0" />
  </joint>

  <joint name="Joint_Elbow_Pitch_Right" type="fixed">
    <parent link="Link_Shoulder_Yaw_Right" />
    <child link="Link_Elbow_Pitch_Right" />
    <origin xyz="0.01 0 -0.197" rpy="0 -1.9 0" />
  </joint>

  <joint name="Joint_Wrist_Yaw_Right" type="fixed">
    <parent link="Link_Elbow_Pitch_Right" />
    <child link="Link_Wrist_Yaw_Right" />
    <origin xyz="-0.01 0 -0.05" rpy="0 0 0" />
  </joint>

  <joint name="Joint_Wrist_Roll_Right" type="fixed">
    <parent link="Link_Wrist_Yaw_Right" />
    <child link="Link_Wrist_Roll_Right" />
    <origin xyz="0 0.005 -0.2395" rpy="0 0 0" />
  </joint>

  <joint name="Joint_Wrist_Pitch_Right" type="fixed">
    <parent link="Link_Wrist_Roll_Right" />
    <child link="Link_Wrist_Pitch_Right" />
    <origin xyz="0 0 0" rpy="0 0 0" />
  </joint>

  <joint name="Right_Hand" type="fixed">
    <parent link="Link_Wrist_Pitch_Right" />
    <child link="Right_Hand" />
    <origin xyz="0 -0.0109 -0.024" rpy="3.14 0 0" />
  </joint>

  <!-- HEAD -->
  <joint name="Joint_Neck_Yaw" type="fixed">
    <parent link="base_link" />
    <child link="Link_Neck_Yaw" />
    <origin xyz="0 0 0.357" rpy="0 0 0" />
  </joint>

  <joint name="Joint_Neck_Pitch" type="fixed">
    <parent link="Link_Neck_Yaw" />
    <child link="Link_Neck_Pitch" />
    <origin xyz="0 0 0" rpy="0 0 0" />
  </joint>

  <!-- <joint name="Joint_" type="revolute">
    <parent link="Link_" />
    <child link="Link_" />
    <origin xyz=" " rpy="0 0 0" />
    <axis xyz=" " />
    <limit lower="- " upper=" " effort="1000" velocity="100.0" />
  </joint> -->
</robot>