<?xml version="1.0"?>
<robot name="igris_C">

  <link name="base_link">
    <inertial>
      <mass value="8.124" />
      <origin xyz="-0.03810 -0.00001 0.08837" />
      <inertia ixx="0.04342" ixy="0.00001" ixz="0.00325" iyy="0.05156" iyz="0.00000" izz="0.04212" />
    </inertial>
    <visual>
      <geometry>
        <mesh filename="/home/robros/isaac_ws/IGRIS_GYM/resources/robots/igris/meshes/igris_c_v1/11_Pelvis.stl" scale="0.01 0.01 0.01"/>
      </geometry>
      <material name="random">
        <color rgba="0.0706 0.0706 0.0706 0.7" />
      </material>
    </visual>
    <collision>
      <geometry>
        <mesh filename="/home/robros/isaac_ws/IGRIS_GYM/resources/robots/igris/meshes/igris_c_v1/11_Pelvis.stl" scale="0.01 0.01 0.01"/>
      </geometry>
    </collision>
  </link>
 
  <link name="Link_Waist_Pitch">
    <inertial>
      <mass value="0.136" />
      <origin xyz="0.00000 0.00000 0.03171" />
      <inertia ixx="0.00005" ixy="0.00000" ixz="0.00000" iyy="0.00011" iyz="0.00000" izz="0.00007" />
    </inertial>
    <visual>
      <geometry>
        <mesh filename="/home/robros/isaac_ws/IGRIS_GYM/resources/robots/igris/meshes/igris_c_v1/12_Waist_Pitch.stl" scale="0.01 0.01 0.01"/>
      </geometry>
      <material name="random">
        <color rgba="0.0706 0.0706 0.0706 0.7" />
      </material>
    </visual>
    <collision>
      <geometry>
        <mesh filename="/home/robros/isaac_ws/IGRIS_GYM/resources/robots/igris/meshes/igris_c_v1/12_Waist_Pitch.stl" scale="0.01 0.01 0.01"/>
      </geometry>
    </collision>
  </link>

  <link name="Link_Waist_Roll">
    <inertial>
      <mass value="0.208" />
      <origin xyz="-0.02403 0.00000 0.01673" />
      <inertia ixx="0.00031" ixy="0.00000" ixz="0.00003" iyy="0.00031" iyz="0.00000" izz="0.00058" />
    </inertial>
    <visual>
      <geometry>
        <mesh filename="/home/robros/isaac_ws/IGRIS_GYM/resources/robots/igris/meshes/igris_c_v1/13_Waist_Roll.stl" scale="0.01 0.01 0.01"/>
      </geometry>
      <material name="random">
        <color rgba="0.0706 0.0706 0.0706 0.7" />
      </material>
    </visual>
    <collision>
      <geometry>
        <mesh filename="/home/robros/isaac_ws/IGRIS_GYM/resources/robots/igris/meshes/igris_c_v1/13_Waist_Roll.stl" scale="0.01 0.01 0.01"/>
      </geometry>
    </collision>
  </link>

  <link name="Link_Waist_Yaw">
    <inertial>
      <mass value="15.792" />
      <origin xyz="0.00140 0.00068 0.17610" />
      <inertia ixx="0.21220" ixy="-0.00103" ixz="0.00936" iyy="0.18410" iyz="-0.00038" izz="0.09851" />
    </inertial>
    <visual>
      <geometry>
        <mesh filename="/home/robros/isaac_ws/IGRIS_GYM/resources/robots/igris/meshes/igris_c_v1/14_Waist_Yaw.stl" scale="0.01 0.01 0.01"/>
      </geometry>
      <material name="random">
        <color rgba="0.0706 0.0706 0.0706 0.7" />
      </material>
    </visual>
    <collision>
      <geometry>
        <mesh filename="/home/robros/isaac_ws/IGRIS_GYM/resources/robots/igris/meshes/igris_c_v1/14_Waist_Yaw.stl" scale="0.01 0.01 0.01"/>
      </geometry>
    </collision>
  </link>

  <link name="Link_Neck_Yaw">
    <inertial>
      <mass value="0.310" />
      <origin xyz="-0.00005 -0.00130 -0.00264" />
      <inertia ixx="0.00017" ixy="0.00000" ixz="0.00000" iyy="0.00010" iyz="0.00001" izz="0.00016" />
    </inertial>
    <visual>
      <geometry>
        <mesh filename="/home/robros/isaac_ws/IGRIS_GYM/resources/robots/igris/meshes/igris_c_v1/15_Neck_Yaw.stl" scale="0.01 0.01 0.01"/>
      </geometry>
      <material name="random">
        <color rgba="0.0706 0.0706 0.0706 0.7" />
      </material>
    </visual>
    <collision>
      <geometry>
        <mesh filename="/home/robros/isaac_ws/IGRIS_GYM/resources/robots/igris/meshes/igris_c_v1/15_Neck_Yaw.stl" scale="0.01 0.01 0.01"/>
      </geometry>
    </collision>
  </link>

  <link name="Link_Neck_Pitch">
    <inertial>
      <mass value="1.468" />
      <origin xyz="0.02850 0.00290 0.12862" />
      <inertia ixx="0.00574" ixy="-0.00008" ixz="0.00025" iyy="0.00727" iyz="0.00013" izz="0.00503" />
    </inertial>
    <visual>
      <geometry>
        <mesh filename="/home/robros/isaac_ws/IGRIS_GYM/resources/robots/igris/meshes/igris_c_v1/16_Neck_Pitch.stl" scale="0.01 0.01 0.01"/>
      </geometry>
      <material name="random">
        <color rgba="0.0706 0.0706 0.0706 0.7" />
      </material>
    </visual>
    <collision>
      <geometry>
        <mesh filename="/home/robros/isaac_ws/IGRIS_GYM/resources/robots/igris/meshes/igris_c_v1/16_Neck_Pitch.stl" scale="0.01 0.01 0.01"/>
      </geometry>
    </collision>
  </link>

  <!-- 211 -->
  <link name="Link_Hip_Pitch_Left">
    <inertial>
      <mass value="1.894" />
      <origin xyz="0.00973 -0.00102 0.00002" />
      <inertia ixx="0.00261" ixy="-0.00001" ixz="0.00000" iyy="0.00267" iyz="0.00000" izz="0.00258" />
    </inertial>
    <visual>
      <geometry>
        <mesh filename="/home/robros/isaac_ws/IGRIS_GYM/resources/robots/igris/meshes/igris_c_v1/211_Hip_Pitch_Left.stl" scale="0.01 0.01 0.01"/>
      </geometry>
      <material name="random">
        <color rgba="0.0706 0.0706 0.0706 0.7" />
      </material>
    </visual>
    <collision>
      <geometry>
        <mesh filename="/home/robros/isaac_ws/IGRIS_GYM/resources/robots/igris/meshes/igris_c_v1/211_Hip_Pitch_Left.stl" scale="0.01 0.01 0.01"/>
      </geometry>
    </collision>
  </link>

  <!-- 212 -->
  <link name="Link_Hip_Roll_Left">
    <inertial>
      <mass value="0.573" />
      <origin xyz="-0.01497 0.00570 -0.03564" />
      <inertia ixx="0.00103" ixy="-0.00006" ixz="0.00012" iyy="0.00226" iyz="0.00006" izz="0.00206" />
    </inertial>
    <visual>
      <geometry>
        <mesh filename="/home/robros/isaac_ws/IGRIS_GYM/resources/robots/igris/meshes/igris_c_v1/212_Hip_Roll_Left.stl" scale="0.01 0.01 0.01"/>
      </geometry>
      <material name="random">
        <color rgba="0.0706 0.0706 0.0706 0.7" />
      </material>
    </visual>
    <collision>
      <geometry>
        <mesh filename="/home/robros/isaac_ws/IGRIS_GYM/resources/robots/igris/meshes/igris_c_v1/212_Hip_Roll_Left.stl" scale="0.01 0.01 0.01"/>
      </geometry>
    </collision>
  </link>

  <!-- 213 -->
    <link name="Link_Hip_Yaw_Left">
    <inertial>
      <mass value="4.813" />
      <origin xyz="-0.01286 -0.00388 -0.10563" />
      <inertia ixx="0.03161" ixy="-0.00007" ixz="-0.00101" iyy="0.03396" iyz="-0.00084" izz="0.01135" />
    </inertial>
    <visual>
      <geometry>
        <mesh filename="/home/robros/isaac_ws/IGRIS_GYM/resources/robots/igris/meshes/igris_c_v1/213_Hip_Yaw_Left.stl" scale="0.01 0.01 0.01"/>
      </geometry>
      <material name="random">
        <color rgba="0.0706 0.0706 0.0706 0.7" />
      </material>
    </visual>
    <collision>
      <geometry>
        <mesh filename="/home/robros/isaac_ws/IGRIS_GYM/resources/robots/igris/meshes/igris_c_v1/213_Hip_Yaw_Left.stl" scale="0.01 0.01 0.01"/>
      </geometry>
    </collision>
  </link>

  <!-- 214 -->
  <link name="Link_Knee_Pitch_Left">
    <inertial>
      <mass value="3.212" />
      <origin xyz="0.01044 0.00096 -0.12320" />
      <inertia ixx="0.02686" ixy="0.00000" ixz="-0.00201" iyy="0.02845" iyz="-0.00048" izz="0.00520" />
    </inertial>
    <visual>
      <geometry>
        <mesh filename="/home/robros/isaac_ws/IGRIS_GYM/resources/robots/igris/meshes/igris_c_v1/214_Knee_Pitch_Left.stl" scale="0.01 0.01 0.01"/>
      </geometry>
      <material name="random">
        <color rgba="0.0706 0.0706 0.0706 0.7" />
      </material>
    </visual>
    <collision>
      <geometry>
        <mesh filename="/home/robros/isaac_ws/IGRIS_GYM/resources/robots/igris/meshes/igris_c_v1/214_Knee_Pitch_Left.stl" scale="0.01 0.01 0.01"/>
      </geometry>
    </collision>
  </link>

  <!-- 215 -->
    <link name="Link_Ankle_Pitch_Left">
    <inertial>
      <mass value="0.084" />
      <origin xyz="0.00000 0.00000 0.00000" />
      <inertia ixx="0.00003" ixy="0.00000" ixz="0.00000" iyy="0.00002" iyz="0.00000" izz="0.00003" />
    </inertial>
    <visual>
      <geometry>
        <mesh filename="/home/robros/isaac_ws/IGRIS_GYM/resources/robots/igris/meshes/igris_c_v1/215_Ankle_Pitch_Left.stl" scale="0.01 0.01 0.01"/>
      </geometry>
      <material name="random">
        <color rgba="0.0706 0.0706 0.0706 0.7" />
      </material>
    </visual>
    <collision>
      <geometry>
        <mesh filename="/home/robros/isaac_ws/IGRIS_GYM/resources/robots/igris/meshes/igris_c_v1/215_Ankle_Pitch_Left.stl" scale="0.01 0.01 0.01"/>
      </geometry>
    </collision>
  </link>

  <!-- 216 -->
  <link name="Link_Ankle_Roll_Left">
    <inertial>
      <mass value="1.303" />
      <origin xyz="0.00930 0.00000 -0.04626" />
      <inertia ixx="0.00032" ixy="0.00000" ixz="0.00016" iyy="0.00094" iyz="0.00000" izz="0.00082" />
    </inertial>
    <visual>
      <geometry>
        <mesh filename="/home/robros/isaac_ws/IGRIS_GYM/resources/robots/igris/meshes/igris_c_v1/216_Ankle_Roll_Left.stl" scale="0.01 0.01 0.01"/>
      </geometry>
      <material name="random">
        <color rgba="0.0706 0.0706 0.0706 0.7" />
      </material>
    </visual>
    <collision>
      <geometry>
        <mesh filename="/home/robros/isaac_ws/IGRIS_GYM/resources/robots/igris/meshes/igris_c_v1/216_Ankle_Roll_Left.stl" scale="0.01 0.01 0.01"/>
      </geometry>
    </collision>
  </link>


<!-- 221 -->
  <link name="Link_Hip_Pitch_Right">
    <inertial>
      <mass value="1.894" />
      <origin xyz="0.00973 0.00102 -0.00002" />
      <inertia ixx="0.00261" ixy="0.00001" ixz="0.00000" iyy="0.00267" iyz="0.00000" izz="0.00258" />
    </inertial>
    <visual>
      <geometry>
        <mesh filename="/home/robros/isaac_ws/IGRIS_GYM/resources/robots/igris/meshes/igris_c_v1/221_Hip_Pitch_Right.stl" scale="0.01 0.01 0.01"/>
      </geometry>
      <material name="random">
        <color rgba="0.0706 0.0706 0.0706 0.7" />
      </material>
    </visual>
    <collision>
      <geometry>
        <mesh filename="/home/robros/isaac_ws/IGRIS_GYM/resources/robots/igris/meshes/igris_c_v1/221_Hip_Pitch_Right.stl" scale="0.01 0.01 0.01"/>
      </geometry>
    </collision>
  </link>

  <!-- 222 -->
  <link name="Link_Hip_Roll_Right">
    <inertial>
      <mass value="0.573" />
      <origin xyz="-0.01497 -0.00570 -0.03564" />
      <inertia ixx="0.00103" ixy="0.00006" ixz="0.00012" iyy="0.00226" iyz="-0.00006" izz="0.00206" />
    </inertial>
    <visual>
      <geometry>
        <mesh filename="/home/robros/isaac_ws/IGRIS_GYM/resources/robots/igris/meshes/igris_c_v1/222_Hip_Roll_Right.stl" scale="0.01 0.01 0.01"/>
      </geometry>
      <material name="random">
        <color rgba="0.0706 0.0706 0.0706 0.7" />
      </material>
    </visual>
    <collision>
      <geometry>
        <mesh filename="/home/robros/isaac_ws/IGRIS_GYM/resources/robots/igris/meshes/igris_c_v1/222_Hip_Roll_Right.stl" scale="0.01 0.01 0.01"/>
      </geometry>
    </collision>
  </link>

  <!-- 223 -->
  <link name="Link_Hip_Yaw_Right">
    <inertial>
      <mass value="4.813" />
      <origin xyz="-0.01286 0.00388 -0.10564" />
      <inertia ixx="0.03161" ixy="0.00007" ixz="-0.00101" iyy="0.03398" iyz="0.00084" izz="0.01137" />
    </inertial>
    <visual>
      <geometry>
        <mesh filename="/home/robros/isaac_ws/IGRIS_GYM/resources/robots/igris/meshes/igris_c_v1/223_Hip_Yaw_Right.stl" scale="0.01 0.01 0.01"/>
      </geometry>
      <material name="random">
        <color rgba="0.0706 0.0706 0.0706 0.7" />
      </material>
    </visual>
    <collision>
      <geometry>
        <mesh filename="/home/robros/isaac_ws/IGRIS_GYM/resources/robots/igris/meshes/igris_c_v1/223_Hip_Yaw_Right.stl" scale="0.01 0.01 0.01"/>
      </geometry>
    </collision>
  </link>

  <!-- 224 -->
  <link name="Link_Knee_Pitch_Right">
    <inertial>
      <mass value="3.212" />
      <origin xyz="0.01044 -0.00096 -0.12320" />
      <inertia ixx="0.02686" ixy="0.00000" ixz="-0.00201" iyy="0.02845" iyz="0.00048" izz="0.00520" />
    </inertial>
    <visual>
      <geometry>
        <mesh filename="/home/robros/isaac_ws/IGRIS_GYM/resources/robots/igris/meshes/igris_c_v1/224_Knee_Pitch_Right.stl" scale="0.01 0.01 0.01"/>
      </geometry>
      <material name="random">
        <color rgba="0.0706 0.0706 0.0706 0.7" />
      </material>
    </visual>
    <collision>
      <geometry>
        <mesh filename="/home/robros/isaac_ws/IGRIS_GYM/resources/robots/igris/meshes/igris_c_v1/224_Knee_Pitch_Right.stl" scale="0.01 0.01 0.01"/>
      </geometry>
    </collision>
  </link>

  <!-- 225 -->
  <link name="Link_Ankle_Pitch_Right">
    <inertial>
      <mass value="0.084" />
      <origin xyz="0 0 0" />
      <inertia ixx="0.00003" ixy="0.00000" ixz="0.00000" iyy="0.00002" iyz="0.00000" izz="0.00003" />
    </inertial>
    <visual>
      <geometry>
        <mesh filename="/home/robros/isaac_ws/IGRIS_GYM/resources/robots/igris/meshes/igris_c_v1/225_Ankle_Pitch_Right.stl" scale="0.01 0.01 0.01"/>
      </geometry>
      <material name="random">
        <color rgba="0.0706 0.0706 0.0706 0.7" />
      </material>
    </visual>
    <collision>
      <geometry>
        <mesh filename="/home/robros/isaac_ws/IGRIS_GYM/resources/robots/igris/meshes/igris_c_v1/225_Ankle_Pitch_Right.stl" scale="0.01 0.01 0.01"/>
      </geometry>
    </collision>
  </link>

  <!-- 226 -->
  <link name="Link_Ankle_Roll_Right">
    <inertial>
      <mass value="1.303" />
      <origin xyz="0.00930 0.00000 -0.04626" />
      <inertia ixx="0.00032" ixy="0.00000" ixz="0.00016" iyy="0.00094" iyz="0.00000" izz="0.00082" />
    </inertial>
    <visual>
      <geometry>
        <mesh filename="/home/robros/isaac_ws/IGRIS_GYM/resources/robots/igris/meshes/igris_c_v1/226_Ankle_Roll_Right.stl" scale="0.01 0.01 0.01"/>
      </geometry>
      <material name="random">
        <color rgba="0.0706 0.0706 0.0706 0.7" />
      </material>
    </visual>
    <collision>
      <geometry>
        <mesh filename="/home/robros/isaac_ws/IGRIS_GYM/resources/robots/igris/meshes/igris_c_v1/226_Ankle_Roll_Right.stl" scale="0.01 0.01 0.01"/>
      </geometry>
    </collision>
  </link>

  <!-- 311 -->
  <link name="Link_Shoulder_Pitch_Left">
    <inertial>
      <mass value="1.105" />
      <origin xyz="0.00039 -0.00330 0.00004" />
      <inertia ixx="0.00118" ixy="0.00001" ixz="0.00000" iyy="0.00097" iyz="0.00000" izz="0.00107" />
    </inertial>
    <visual>
      <geometry>
        <mesh filename="/home/robros/isaac_ws/IGRIS_GYM/resources/robots/igris/meshes/igris_c_v1/311_Shoulder_Pitch_Left.stl" scale="0.01 0.01 0.01"/>
      </geometry>
      <material name="random">
        <color rgba="0.0706 0.0706 0.0706 0.7" />
      </material>
    </visual>
    <collision>
      <geometry>
        <mesh filename="/home/robros/isaac_ws/IGRIS_GYM/resources/robots/igris/meshes/igris_c_v1/311_Shoulder_Pitch_Left.stl" scale="0.01 0.01 0.01"/>
      </geometry>
    </collision>
  </link>

  <!-- 312 -->
  <link name="Link_Shoulder_Roll_Left">
    <inertial>
      <mass value="0.253" />
      <origin xyz="0.02322 0.00000 -0.03100" />
      <inertia ixx="0.00046" ixy="0.00000" ixz="-0.00013" iyy="0.00046" iyz="0.00000" izz="0.00034" />
    </inertial>
    <visual>
      <geometry>
        <mesh filename="/home/robros/isaac_ws/IGRIS_GYM/resources/robots/igris/meshes/igris_c_v1/312_Shoulder_Roll_Left.stl" scale="0.01 0.01 0.01"/>
      </geometry>
      <material name="random">
        <color rgba="0.0706 0.0706 0.0706 0.7" />
      </material>
    </visual>
    <collision>
      <geometry>
        <mesh filename="/home/robros/isaac_ws/IGRIS_GYM/resources/robots/igris/meshes/igris_c_v1/312_Shoulder_Roll_Left.stl" scale="0.01 0.01 0.01"/>
      </geometry>
    </collision>
  </link>

  <!-- 313 -->
  <link name="Link_Shoulder_Yaw_Left">
    <inertial>
      <mass value="2.144" />
      <origin xyz="0.00289 0.00039 -0.14632" />
      <inertia ixx="0.00708" ixy="0.00000" ixz="0.00045" iyy="0.00723" iyz="0.00002" izz="0.00213" />
    </inertial>
    <visual>
      <geometry>
        <mesh filename="/home/robros/isaac_ws/IGRIS_GYM/resources/robots/igris/meshes/igris_c_v1/313_Shoulder_Yaw_Left.stl" scale="0.01 0.01 0.01"/>
      </geometry>
      <material name="random">
        <color rgba="0.0706 0.0706 0.0706 0.7" />
      </material>
    </visual>
    <collision>
      <geometry>
        <mesh filename="/home/robros/isaac_ws/IGRIS_GYM/resources/robots/igris/meshes/igris_c_v1/313_Shoulder_Yaw_Left.stl" scale="0.01 0.01 0.01"/>
      </geometry>
    </collision>
  </link>

  <!-- 314 -->
  <link name="Link_Elbow_Pitch_Left">
    <inertial>
      <mass value="0.137" />
      <origin xyz="-0.00506 0.02516 -0.02257" />
      <inertia ixx="0.00017" ixy="-0.00001" ixz="-0.00002" iyy="0.00017" iyz="-0.00005" izz="0.00013" />
    </inertial>
    <visual>
      <geometry>
        <mesh filename="/home/robros/isaac_ws/IGRIS_GYM/resources/robots/igris/meshes/igris_c_v1/314_Elbow_Pitch_Left.stl" scale="0.01 0.01 0.01"/>
      </geometry>
      <material name="random">
        <color rgba="0.0706 0.0706 0.0706 0.7" />
      </material>
    </visual>
    <collision>
      <geometry>
        <mesh filename="/home/robros/isaac_ws/IGRIS_GYM/resources/robots/igris/meshes/igris_c_v1/314_Elbow_Pitch_Left.stl" scale="0.01 0.01 0.01"/>
      </geometry>
    </collision>
  </link>

  <!-- 315 -->
  <link name="Link_Elbow_Yaw_Left">
    <inertial>
      <mass value="2.299" />
      <origin xyz="-0.00019 0.00001 -0.08347" />
      <inertia ixx="0.00819" ixy="0.00000" ixz="-0.00004" iyy="0.00912" iyz="0.00006" izz="0.00302" />
    </inertial>
    <visual>
      <geometry>
        <mesh filename="/home/robros/isaac_ws/IGRIS_GYM/resources/robots/igris/meshes/igris_c_v1/315_Elbow_Yaw_Left.stl" scale="0.01 0.01 0.01"/>
      </geometry>
      <material name="random">
        <color rgba="0.0706 0.0706 0.0706 0.7" />
      </material>
    </visual>
    <collision>
      <geometry>
        <mesh filename="/home/robros/isaac_ws/IGRIS_GYM/resources/robots/igris/meshes/igris_c_v1/315_Elbow_Yaw_Left.stl" scale="0.01 0.01 0.01"/>
      </geometry>
    </collision>
  </link>


  <!-- 316 -->
  <link name="Link_Wrist_Roll_Left">
    <inertial>
      <mass value="0.012" />
      <origin xyz="0.00000 0.00604 0.00031" />
      <inertia ixx="0.00000" ixy="0.00000" ixz="0.00000" iyy="0.00000" iyz="0.00000" izz="0.00000" />
    </inertial>
    <visual>
      <geometry>
        <mesh filename="/home/robros/isaac_ws/IGRIS_GYM/resources/robots/igris/meshes/igris_c_v1/316_Wrist_Roll_Left.stl" scale="0.01 0.01 0.01"/>
      </geometry>
      <material name="random">
        <color rgba="0.0706 0.0706 0.0706 0.7" />
      </material>
    </visual>
    <collision>
      <geometry>
        <mesh filename="/home/robros/isaac_ws/IGRIS_GYM/resources/robots/igris/meshes/igris_c_v1/316_Wrist_Roll_Left.stl" scale="0.01 0.01 0.01"/>
      </geometry>
    </collision>
  </link>

  <!-- 317 -->
  <link name="Link_Wrist_Pitch_Left">
    <inertial>
      <mass value="0.020" />
      <origin xyz="0 0.01019 -0.01687" />
      <inertia ixx="0.00000" ixy="0.00000" ixz="0.00000" iyy="0.00000" iyz="0.00000" izz="0.00000" />
    </inertial>
    <visual>
      <geometry>
        <mesh filename="/home/robros/isaac_ws/IGRIS_GYM/resources/robots/igris/meshes/igris_c_v1/317_Wrist_Pitch_Left.stl" scale="0.01 0.01 0.01"/>
      </geometry>
      <material name="random">
        <color rgba="0.0706 0.0706 0.0706 0.7" />
      </material>
    </visual>
    <collision>
      <geometry>
        <mesh filename="/home/robros/isaac_ws/IGRIS_GYM/resources/robots/igris/meshes/igris_c_v1/317_Wrist_Pitch_Left.stl" scale="0.01 0.01 0.01"/>
      </geometry>
    </collision>
  </link>

  <link name="Left_Hand"> 
    <inertial>
      <mass value="0.03" />
      <origin xyz="0.00000 0.0 -0.07" />
      <inertia ixx="0.00000" ixy="0.00000" ixz="0.00000" iyy="0.00000" iyz="0.00000" izz="0.00000" />
    </inertial>
    <visual>
      <geometry>
        <mesh filename="/home/robros/isaac_ws/IGRIS_GYM/resources/robots/igris/meshes/igris_c_v1/Left_Hand.stl" scale="0.001 0.001 0.001"/>
      </geometry>
      <material name="random">
        <color rgba="0.0706 0.0706 0.0706 0.7" />
      </material>
    </visual>
   <collision>
      <geometry>
        <mesh filename="/home/robros/isaac_ws/IGRIS_GYM/resources/robots/igris/meshes/igris_c_v1/Left_Hand.stl" scale="0.001 0.001 0.001"/>
      </geometry>
   </collision>
  </link>

  <!-- 321 -->
  <link name="Link_Shoulder_Pitch_Right">
    <inertial>
      <mass value="1.105" />
      <origin xyz="0.00039 0.00330 -0.00004" />
      <inertia ixx="0.00118" ixy="-0.00001" ixz="0.00000" iyy="0.00097" iyz="0.00000" izz="0.00107" />
    </inertial>
    <visual>
      <geometry>
        <mesh filename="/home/robros/isaac_ws/IGRIS_GYM/resources/robots/igris/meshes/igris_c_v1/321_Shoulder_Pitch_Right.stl" scale="0.01 0.01 0.01"/>
      </geometry>
      <material name="random">
        <color rgba="0.0706 0.0706 0.0706 0.7" />
      </material>
    </visual>
    <collision>
      <geometry>
        <mesh filename="/home/robros/isaac_ws/IGRIS_GYM/resources/robots/igris/meshes/igris_c_v1/321_Shoulder_Pitch_Right.stl" scale="0.01 0.01 0.01"/>
      </geometry>
    </collision>
  </link>

  <!-- 322 -->
  <link name="Link_Shoulder_Roll_Right">
    <inertial>
      <mass value="0.253" />
      <origin xyz="0.02322 0.00000 -0.03100" />
      <inertia ixx="0.00046" ixy="0.00000" ixz="-0.00013" iyy="0.00046" iyz="0.00000" izz="0.00034" />
    </inertial>
    <visual>
      <geometry>
        <mesh filename="/home/robros/isaac_ws/IGRIS_GYM/resources/robots/igris/meshes/igris_c_v1/322_Shoulder_Roll_Right.stl" scale="0.01 0.01 0.01"/>
      </geometry>
      <material name="random">
        <color rgba="0.0706 0.0706 0.0706 0.7" />
      </material>
    </visual>
    <collision>
      <geometry>
        <mesh filename="/home/robros/isaac_ws/IGRIS_GYM/resources/robots/igris/meshes/igris_c_v1/322_Shoulder_Roll_Right.stl" scale="0.01 0.01 0.01"/>
      </geometry>
    </collision>
  </link>

  <!-- 332 -->
  <link name="Link_Shoulder_Yaw_Right">
    <inertial>
      <mass value="2.144" />
      <origin xyz="0.00289 -0.00018 -0.14632" />
      <inertia ixx="0.00708" ixy="0.00001" ixz="0.00045" iyy="0.00723" iyz="-0.00002" izz="0.00213" />
    </inertial>
    <visual>
      <geometry>
        <mesh filename="/home/robros/isaac_ws/IGRIS_GYM/resources/robots/igris/meshes/igris_c_v1/323_Shoulder_Yaw_Right.stl" scale="0.01 0.01 0.01"/>
      </geometry>
      <material name="random">
        <color rgba="0.0706 0.0706 0.0706 0.7" />
      </material>
    </visual>
    <collision>
      <geometry>
        <mesh filename="/home/robros/isaac_ws/IGRIS_GYM/resources/robots/igris/meshes/igris_c_v1/323_Shoulder_Yaw_Right.stl" scale="0.01 0.01 0.01"/>
      </geometry>
    </collision>
  </link>

  <!-- 324 -->
  <link name="Link_Elbow_Pitch_Right">
    <inertial>
      <mass value="0.137" />
      <origin xyz="-0.00506 -0.02516 -0.02257" />
      <inertia ixx="0.00017" ixy="0.00001" ixz="-0.00002" iyy="0.00017" iyz="0.00005" izz="0.00013" />
    </inertial>
    <visual>
      <geometry>
        <mesh filename="/home/robros/isaac_ws/IGRIS_GYM/resources/robots/igris/meshes/igris_c_v1/324_Elbow_Pitch_Right.stl" scale="0.01 0.01 0.01"/>
      </geometry>
      <material name="random">
        <color rgba="0.0706 0.0706 0.0706 0.7" />
      </material>
    </visual>
    <collision>
      <geometry>
        <mesh filename="/home/robros/isaac_ws/IGRIS_GYM/resources/robots/igris/meshes/igris_c_v1/324_Elbow_Pitch_Right.stl" scale="0.01 0.01 0.01"/>
      </geometry>
    </collision>
  </link>

  <!-- 325 -->
  <link name="Link_Elbow_Yaw_Right">
    <inertial>
      <mass value="2.299" />
      <origin xyz="-0.00077 -0.00035 -0.08347" />
      <inertia ixx="0.00819" ixy="0.00000" ixz="-0.00011" iyy="0.00912" iyz="-0.00010" izz="0.00302" />
    </inertial>
    <visual>
      <geometry>
        <mesh filename="/home/robros/isaac_ws/IGRIS_GYM/resources/robots/igris/meshes/igris_c_v1/325_Elbow_Yaw_Right.stl" scale="0.01 0.01 0.01"/>
      </geometry>
      <material name="random">
        <color rgba="0.0706 0.0706 0.0706 0.7" />
      </material>
    </visual>
    <collision>
      <geometry>
        <mesh filename="/home/robros/isaac_ws/IGRIS_GYM/resources/robots/igris/meshes/igris_c_v1/325_Elbow_Yaw_Right.stl" scale="0.01 0.01 0.01"/>
      </geometry>
    </collision>
  </link>

  <!-- 326 -->
  <link name="Link_Wrist_Roll_Right">
    <inertial>
      <mass value="0.012" />
      <origin xyz="0.00000 -0.00604 0.00031" />
      <inertia ixx="0.00000" ixy="0.00000" ixz="0.00000" iyy="0.00000" iyz="0.00000" izz="0.00000" />
    </inertial>
    <visual>
      <geometry>
        <mesh filename="/home/robros/isaac_ws/IGRIS_GYM/resources/robots/igris/meshes/igris_c_v1/326_Wrist_Roll_Right.stl" scale="0.01 0.01 0.01"/>
      </geometry>
      <material name="random">
        <color rgba="0.0706 0.0706 0.0706 0.7" />
      </material>
    </visual>
    <collision>
      <geometry>
        <mesh filename="/home/robros/isaac_ws/IGRIS_GYM/resources/robots/igris/meshes/igris_c_v1/326_Wrist_Roll_Right.stl" scale="0.01 0.01 0.01"/>
      </geometry>
    </collision>
  </link>

  <!-- 327 -->
  <link name="Link_Wrist_Pitch_Right">
    <inertial>
      <mass value="0.020" />
      <origin xyz="0.00000 -0.01019 -0.01687" />
      <inertia ixx="0.00000" ixy="0.00000" ixz="0.00000" iyy="0.00000" iyz="0.00000" izz="0.00000" />
    </inertial>
    <visual>
      <geometry>
        <mesh filename="/home/robros/isaac_ws/IGRIS_GYM/resources/robots/igris/meshes/igris_c_v1/327_Wrist_Pitch_Right.stl" scale="0.01 0.01 0.01"/>
      </geometry>
      <material name="random">
        <color rgba="0.0706 0.0706 0.0706 0.7" />
      </material>
    </visual>
    <collision>
      <geometry>
        <mesh filename="/home/robros/isaac_ws/IGRIS_GYM/resources/robots/igris/meshes/igris_c_v1/327_Wrist_Pitch_Right.stl" scale="0.01 0.01 0.01"/>
      </geometry>
    </collision>
  </link>

  

  <link name="Right_Hand">
    <inertial>
      <mass value="0.03" />
      <origin xyz="0.00000 0.0 -0.07" />
      <inertia ixx="0.00000" ixy="0.00000" ixz="0.00000" iyy="0.00000" iyz="0.00000" izz="0.00000" />
    </inertial>
    <visual>
      <geometry>
        <mesh filename="/home/robros/isaac_ws/IGRIS_GYM/resources/robots/igris/meshes/igris_c_v1/Right_Hand.stl" scale="0.001 0.001 0.001"/>
      </geometry>
      <material name="random">
        <color rgba="0.0706 0.0706 0.0706 0.7" />
      </material>
    </visual>
   <collision>
      <geometry>
        <mesh filename="/home/robros/isaac_ws/IGRIS_GYM/resources/robots/igris/meshes/igris_c_v1/Right_Hand.stl" scale="0.001 0.001 0.001"/>
      </geometry>
   </collision>
  </link>



  <joint name="Joint_Hip_Pitch_Left" type="revolute">
    <parent link="base_link" />
    <child link="Link_Hip_Pitch_Left" />
    <origin xyz="0 0.0897 0" rpy="0 0 0" />
    <axis xyz="0 1 0" />
    <limit lower="-2.042035225" upper="0.523598776" effort="1000" velocity="5.0" />
  </joint>

  <joint name="Joint_Hip_Roll_Left" type="revolute">
    <parent link="Link_Hip_Pitch_Left" />
    <child link="Link_Hip_Roll_Left" />
    <origin xyz="0 0 0" rpy="0 0 0" />
    <axis xyz="1 0 0" />
    <limit lower="-0.331612558" upper="2.35619449" effort="1000" velocity="5.0" />
  </joint>

  <joint name="Joint_Hip_Yaw_Left" type="revolute">
    <parent link="Link_Hip_Roll_Left" />
    <child link="Link_Hip_Yaw_Left" />
    <origin xyz="0.002 0 -0.076" rpy="0 0 0" />
    <axis xyz="0 0 1" />
    <limit lower="-1.570796327" upper="1.570796327" effort="1000" velocity="5.0" />
  </joint>

  <joint name="Joint_Knee_Pitch_Left" type="revolute">
    <parent link="Link_Hip_Yaw_Left" />
    <child link="Link_Knee_Pitch_Left" />
    <origin xyz="-0.055 0 -0.263" rpy="0 0 0" />
    <axis xyz="0 1 0" />
    <limit lower="0" upper="2.28638132" effort="1000" velocity="5.0" />
  </joint>

  <joint name="Joint_Ankle_Pitch_Left" type="revolute">
    <parent link="Link_Knee_Pitch_Left" />
    <child link="Link_Ankle_Pitch_Left" />
    <origin xyz="0.005 0 -0.34" rpy="0 0 0" />
    <axis xyz="0 1 0" />
    <limit lower="-0.698131701" upper="0.698131701" effort="1000" velocity="5.0" />
  </joint>

  <joint name="Joint_Ankle_Roll_Left" type="revolute">
    <parent link="Link_Ankle_Pitch_Left" />
    <child link="Link_Ankle_Roll_Left" />
    <origin xyz="0 0 0" rpy="0 0 0" />
    <axis xyz="1 0 0" />
    <limit lower="-0.261799388" upper="0.261799388" effort="1000" velocity="5.0" />
  </joint>

  <joint name="Joint_Hip_Pitch_Right" type="revolute">
    <parent link="base_link" />
    <child link="Link_Hip_Pitch_Right" />
    <origin xyz="0 -0.0897 0" rpy="0 0 0" />
    <axis xyz="0 1 0" />
    <limit lower="-2.059488517" upper="0.523598776" effort="1000" velocity="5.0" />
  </joint>

  <joint name="Joint_Hip_Roll_Right" type="revolute">
    <parent link="Link_Hip_Pitch_Right" />
    <child link="Link_Hip_Roll_Right" />
    <origin xyz="0 0 0" rpy="0 0 0" />
    <axis xyz="1 0 0" />
    <limit lower="-2.35619449" upper="0.331612558" effort="1000" velocity="5.0" />
  </joint>

  <joint name="Joint_Hip_Yaw_Right" type="revolute">
    <parent link="Link_Hip_Roll_Right" />
    <child link="Link_Hip_Yaw_Right" />
    <origin xyz="0.002 0 -0.076" rpy="0 0 0" />
    <axis xyz="0 0 1" />
    <limit lower="-1.570796327" upper="1.570796327" effort="1000" velocity="5.0" />
  </joint>

  <joint name="Joint_Knee_Pitch_Right" type="revolute">
    <parent link="Link_Hip_Yaw_Right" />
    <child link="Link_Knee_Pitch_Right" />
    <origin xyz="-0.055 0 -0.263" rpy="0 0 0" />
    <axis xyz="0 1 0" />
    <limit lower="0" upper="2.28638132" effort="1000" velocity="5.0" />
  </joint>

  <joint name="Joint_Ankle_Pitch_Right" type="revolute">
    <parent link="Link_Knee_Pitch_Right" />
    <child link="Link_Ankle_Pitch_Right" />
    <origin xyz="0.005 0 -0.34" rpy="0 0 0" />
    <axis xyz="0 1 0" />
    <limit lower="-0.698131701" upper="0.698131701" effort="1000" velocity="5.0" />
  </joint>

  <joint name="Joint_Ankle_Roll_Right" type="revolute">
    <parent link="Link_Ankle_Pitch_Right" />
    <child link="Link_Ankle_Roll_Right" />
    <origin xyz="0 0 0" rpy="0 0 0" />
    <axis xyz="1 0 0" />
    <limit lower="-0.261799388" upper="0.261799388" effort="1000" velocity="5.0" />
  </joint>
  
  <joint name="Joint_Waist_Pitch" type="revolute">
    <parent link="base_link" />
    <child link="Link_Waist_Pitch" />
    <origin xyz="0.0115 0 0.14" rpy="0 0 0" />
    <axis xyz="0 1 0" />
    <limit lower="-0.345575192" upper="0.872664626" effort="1000" velocity="5.0" />
  </joint>
 
  <joint name="Joint_Waist_Roll" type="revolute">
    <parent link="Link_Waist_Pitch" />
    <child link="Link_Waist_Roll" />
    <origin xyz="0 0 0.04" rpy="0 0 0" />
    <axis xyz="1 0 0" />
    <limit lower="-0.453785606" upper="0.453785606" effort="1000" velocity="5.0" />
  </joint>
  
  <joint name="Joint_Waist_Yaw" type="revolute">
    <parent link="Link_Waist_Roll" />
    <child link="Link_Waist_Yaw" />
    <origin xyz="-0.05 0 0.026" rpy="0 0 0" />
    <axis xyz="0 0 1" />
    <limit lower="-1.570796327" upper="1.570796327" effort="1000" velocity="5.0" />
  </joint>

  <joint name="Joint_Neck_Yaw" type="revolute">
    <parent link="Link_Waist_Yaw" />
    <child link="Link_Neck_Yaw" />
    <origin xyz="0 0 0.357" rpy="0 0 0" />
    <axis xyz="0 0 1" />
    <limit lower="-1.221730476" upper="1.221730476" effort="1000" velocity="5.0" />
  </joint>

  <joint name="Joint_Neck_Pitch" type="revolute">
    <parent link="Link_Neck_Yaw" />
    <child link="Link_Neck_Pitch" />
    <origin xyz="0 0 0" rpy="0 0 0" />
    <axis xyz="0 1 0" />
    <limit lower="-0.523598776" upper="0.523598776" effort="1000" velocity="5.0" />
  </joint>

  <joint name="Joint_Shoulder_Pitch_Left" type="revolute">
    <parent link="Link_Waist_Yaw" />
    <child link="Link_Shoulder_Pitch_Left" />
    <origin xyz="0 0.171 0.266" rpy="0 0 0" />
    <axis xyz="0 1 0" />
    <limit lower="-3.141592654" upper="1.047197551" effort="1000" velocity="5.0" />
  </joint>

  <joint name="Joint_Shoulder_Roll_Left" type="revolute">
    <parent link="Link_Shoulder_Pitch_Left" />
    <child link="Link_Shoulder_Roll_Left" />
    <origin xyz="0 0 0" rpy="0 0 0" />
    <axis xyz="1 0 0" />
    <limit lower="-0.174532925" upper="3.141592654" effort="1000" velocity="5.0" />
  </joint>

  <joint name="Joint_Shoulder_Yaw_Left" type="revolute">
    <parent link="Link_Shoulder_Roll_Left" />
    <child link="Link_Shoulder_Yaw_Left" />
    <origin xyz="0 0 0" rpy="0 0 0" />
    <axis xyz="0 0 1" />
    <limit lower="-1.570796327" upper="1.570796327" effort="1000" velocity="5.0" />
  </joint>

  <joint name="Joint_Elbow_Pitch_Left" type="revolute">
    <parent link="Link_Shoulder_Yaw_Left" />
    <child link="Link_Elbow_Pitch_Left" />
    <origin xyz="0.01 0 -0.197" rpy="0 0 0" />
    <axis xyz="0 1 0" />
    <limit lower="-2.094395102" upper="0" effort="1000" velocity="5.0" />
  </joint>

  <joint name="Joint_Elbow_Yaw_Left" type="revolute">
    <parent link="Link_Elbow_Pitch_Left" />
    <child link="Link_Elbow_Yaw_Left" />
    <origin xyz="-0.01 0 -0.05" rpy="0 0 0" />
    <axis xyz="0 0 1" />
    <limit lower="-1.570796327" upper="1.570796327" effort="1000" velocity="5.0" />
  </joint>

  <joint name="Joint_Wrist_Roll_Left" type="revolute">
    <parent link="Link_Elbow_Yaw_Left" />
    <child link="Link_Wrist_Roll_Left" />
    <origin xyz="0 -0.005 -0.2395 " rpy="0 0 0" />
    <axis xyz="1 0 0" />
    <limit lower="-0.872664626" upper="1.221730476" effort="1000" velocity="5.0" />
  </joint>

  <joint name="Joint_Wrist_Pitch_Left" type="revolute">
    <parent link="Link_Wrist_Roll_Left" />
    <child link="Link_Wrist_Pitch_Left" />
    <origin xyz="0 0 0" rpy="0 0 0" />
    <axis xyz="0 1 0" />
    <limit lower="-0.698131701" upper="0.698131701" effort="1000" velocity="5.0" />
  </joint>

  <joint name="Left_Hand" type="fixed">
    <parent link="Link_Wrist_Pitch_Left" />
    <child link="Left_Hand" />
    <origin xyz="0 0 -0.029" rpy="0 3.14 0" />
  </joint>

  <joint name="Joint_Shoulder_Pitch_Right" type="revolute">
    <parent link="Link_Waist_Yaw" />
    <child link="Link_Shoulder_Pitch_Right" />
    <origin xyz="0 -0.171 0.266" rpy="0 0 0" />
    <axis xyz="0 1 0" />
    <limit lower="-3.141592654" upper="1.047197551" effort="1000" velocity="5.0" />
  </joint>

  <joint name="Joint_Shoulder_Roll_Right" type="revolute">
    <parent link="Link_Shoulder_Pitch_Right" />
    <child link="Link_Shoulder_Roll_Right" />
    <origin xyz="0 0 0" rpy="0 0 0" />
    <axis xyz="1 0 0" />
    <limit lower="-3.141592654" upper="0.174532925" effort="1000" velocity="5.0" />
  </joint>

  <joint name="Joint_Shoulder_Yaw_Right" type="revolute">
    <parent link="Link_Shoulder_Roll_Right" />
    <child link="Link_Shoulder_Yaw_Right" />
    <origin xyz="0 0 0" rpy="0 0 0" />
    <axis xyz="0 0 1" />
    <limit lower="-1.570796327" upper="1.570796327" effort="1000" velocity="5.0" />
  </joint>

  <joint name="Joint_Elbow_Pitch_Right" type="revolute">
    <parent link="Link_Shoulder_Yaw_Right" />
    <child link="Link_Elbow_Pitch_Right" />
    <origin xyz="0.01 0 -0.197" rpy="0 0 0" />
    <axis xyz="0 1 0" />
    <limit lower="-2.094395102" upper="0" effort="1000" velocity="5.0" />
  </joint>

  <joint name="Joint_Elbow_Yaw_Right" type="revolute">
    <parent link="Link_Elbow_Pitch_Right" />
    <child link="Link_Elbow_Yaw_Right" />
    <origin xyz="-0.01 0 -0.05" rpy="0 0 0" />
    <axis xyz="0 0 1" />
    <limit lower="-1.570796327" upper="1.570796327" effort="1000" velocity="5.0" />
  </joint>

  <joint name="Joint_Wrist_Roll_Right" type="revolute">
    <parent link="Link_Elbow_Yaw_Right" />
    <child link="Link_Wrist_Roll_Right" />
    <origin xyz="0 0.005 -0.2395" rpy="0 0 0" />
    <axis xyz="1 0 0"/>
    <limit lower="-1.221730476" upper="0.872664626" effort="1000" velocity="5.0" />
  </joint>

  <joint name="Joint_Wrist_Pitch_Right" type="revolute">
    <parent link="Link_Wrist_Roll_Right" />
    <child link="Link_Wrist_Pitch_Right" />
    <origin xyz="0 0 0" rpy="0 0 0" />
    <axis xyz="0 1 0" />
    <limit lower="-0.698131701" upper="0.698131701" effort="1000" velocity="5.0" />
  </joint>

  <joint name="Right_Hand" type="fixed">
    <parent link="Link_Wrist_Pitch_Right" />
    <child link="Right_Hand" />
    <origin xyz="0 0 -0.029" rpy="0 -3.14 3.14" />
  </joint>
</robot>